ply
format ascii 1.0
comment : MagicaVoxel @ Ephtracy
element vertex 953
property float x
property float y
property float z
property uchar red
property uchar green
property uchar blue
end_header
9 8 20 0 102 153
10 8 20 0 102 153
11 8 20 0 102 153
8 9 20 0 102 153
9 9 20 0 102 153
10 9 20 0 102 153
11 9 20 0 102 153
12 9 20 0 102 153
8 10 20 0 102 153
9 10 20 0 102 153
10 10 20 0 102 153
11 10 20 0 102 153
12 10 20 0 102 153
8 11 20 0 102 153
9 11 20 0 102 153
10 11 20 0 102 153
11 11 20 0 102 153
12 11 20 0 102 153
8 12 20 0 102 153
9 12 20 0 102 153
10 12 20 0 102 153
11 12 20 0 102 153
12 12 20 0 102 153
15 7 34 0 102 153
15 6 34 0 102 153
5 6 34 0 102 153
9 6 21 0 102 153
10 6 21 0 102 153
11 6 21 0 102 153
12 4 32 0 102 153
8 7 21 0 102 153
9 7 21 0 102 153
10 7 21 0 102 153
11 7 21 0 102 153
12 7 21 0 102 153
7 4 32 0 102 153
17 7 33 0 102 153
7 8 21 0 102 153
8 8 21 0 102 153
8 17 23 0 102 153
12 17 23 0 102 153
12 18 24 0 102 153
12 8 21 0 102 153
13 8 21 0 102 153
3 7 34 0 102 153
17 7 34 0 102 153
7 9 21 0 102 153
7 18 25 0 102 153
13 18 25 0 102 153
8 18 25 0 102 153
12 18 25 0 102 153
8 21 26 0 102 153
13 9 21 0 102 153
4 7 35 0 102 153
16 7 35 0 102 153
7 10 21 0 102 153
12 21 26 0 102 153
8 20 26 0 102 153
12 20 26 0 102 153
8 19 26 0 102 153
12 19 26 0 102 153
13 10 21 0 102 153
17 6 34 0 102 153
3 6 34 0 102 153
7 11 21 0 102 153
7 20 26 0 102 153
13 20 26 0 102 153
4 17 28 0 102 153
16 17 28 0 102 153
5 19 28 0 102 153
13 11 21 0 102 153
4 7 34 204 153 153
17 6 33 0 102 153
7 12 21 0 102 153
15 19 28 0 102 153
5 18 28 0 102 153
15 18 28 0 102 153
5 17 27 0 102 153
15 17 27 0 102 153
13 12 21 0 102 153
4 6 35 0 102 153
17 6 32 0 102 153
7 13 21 0 102 153
8 13 21 0 102 153
9 13 21 0 102 153
10 13 21 0 102 153
11 13 21 0 102 153
12 13 21 0 102 153
13 13 21 0 102 153
5 7 34 0 102 153
7 21 26 0 102 153
6 20 28 0 102 153
7 23 26 0 102 153
6 21 27 0 102 153
13 23 26 0 102 153
14 20 28 0 102 153
13 21 26 0 102 153
4 7 33 204 153 153
4 8 33 0 102 153
16 7 33 204 153 153
9 5 22 0 102 153
10 5 22 0 102 153
11 5 22 0 102 153
6 6 33 0 102 153
8 6 22 0 102 153
10 25 32 0 102 153
10 24 33 0 102 153
10 23 34 0 102 153
12 6 22 0 102 153
14 6 33 0 102 153
3 6 32 0 102 153
7 7 22 0 102 153
10 22 35 0 102 153
11 20 35 0 102 153
9 20 35 0 102 153
10 21 35 0 102 153
10 20 36 0 102 153
13 7 22 0 102 153
16 6 35 0 102 153
4 7 32 0 102 153
6 8 22 0 102 153
11 19 35 0 102 153
9 19 35 0 102 153
10 19 36 0 102 153
11 18 36 0 102 153
9 18 36 0 102 153
10 18 37 0 102 153
10 17 37 0 102 153
14 8 22 0 102 153
16 7 32 0 102 153
5 9 22 0 102 153
6 9 22 0 102 153
9 17 36 0 102 153
11 17 36 0 102 153
9 16 37 0 102 153
11 16 37 0 102 153
9 15 37 0 102 153
11 15 37 0 102 153
9 14 37 0 102 153
14 9 22 0 102 153
15 9 22 0 102 153
9 1 27 204 153 153
5 10 22 0 102 153
6 10 22 0 102 153
11 14 37 0 102 153
9 13 38 0 102 153
11 13 38 0 102 153
9 12 38 0 102 153
11 12 38 0 102 153
9 13 37 0 102 153
11 13 37 0 102 153
14 10 22 0 102 153
15 10 22 0 102 153
11 1 27 204 153 153
16 8 34 0 102 153
5 11 22 0 102 153
6 11 22 0 102 153
10 16 37 0 102 153
10 15 38 0 102 153
10 14 38 0 102 153
10 13 38 0 102 153
10 12 38 0 102 153
10 11 38 0 102 153
9 12 37 0 102 153
14 11 22 0 102 153
15 11 22 0 102 153
3 7 33 0 102 153
5 12 22 0 102 153
6 12 22 0 102 153
11 12 37 0 102 153
9 11 37 0 102 153
11 11 37 0 102 153
9 10 37 0 102 153
11 10 37 0 102 153
10 10 37 0 102 153
10 9 37 0 102 153
14 12 22 0 102 153
15 12 22 0 102 153
4 6 31 0 102 153
6 13 22 0 102 153
11 9 37 0 102 153
9 9 37 0 102 153
8 12 36 0 102 153
12 12 36 0 102 153
8 9 36 0 102 153
12 9 36 0 102 153
7 9 35 0 102 153
14 13 22 0 102 153
16 6 31 0 102 153
4 6 32 0 102 153
7 14 22 0 102 153
8 14 22 0 102 153
9 14 22 0 102 153
10 14 22 0 102 153
11 14 22 0 102 153
12 14 22 0 102 153
13 14 22 0 102 153
16 6 32 0 102 153
5 7 33 204 153 153
14 21 27 0 102 153
13 9 35 0 102 153
8 8 35 0 102 153
12 8 35 0 102 153
8 11 36 0 102 153
15 7 33 204 153 153
16 8 33 0 102 153
3 6 35 0 102 153
3 6 33 0 102 153
9 4 23 238 238 238
10 4 23 153 51 102
11 4 23 238 238 238
7 5 23 0 102 153
8 5 23 0 102 153
12 11 36 0 102 153
8 10 36 0 102 153
12 10 36 0 102 153
12 5 23 0 102 153
13 5 23 0 102 153
7 2 25 204 153 153
6 6 23 0 102 153
7 6 23 0 102 153
9 8 36 0 102 153
11 8 36 0 102 153
10 8 36 0 102 153
10 7 35 0 102 153
2 12 30 0 102 153
13 6 23 0 102 153
14 6 23 0 102 153
13 2 25 204 153 153
5 7 23 0 102 153
6 7 23 0 102 153
18 12 30 0 102 153
2 13 30 0 102 153
18 13 30 0 102 153
2 14 31 0 102 153
18 14 31 0 102 153
2 13 31 0 102 153
18 13 31 0 102 153
14 7 23 0 102 153
15 7 23 0 102 153
7 2 26 204 153 153
5 8 23 0 102 153
2 12 31 0 102 153
18 12 31 0 102 153
2 13 32 0 102 153
18 13 32 0 102 153
3 16 31 0 102 153
17 16 31 0 102 153
3 15 30 0 102 153
17 15 30 0 102 153
3 14 29 0 102 153
15 8 23 0 102 153
13 2 26 204 153 153
4 9 23 0 102 153
17 14 29 0 102 153
3 14 30 0 102 153
17 14 30 0 102 153
3 15 31 0 102 153
17 15 31 0 102 153
3 21 31 0 102 153
17 21 31 0 102 153
3 22 31 0 102 153
17 22 31 0 102 153
2 23 31 0 102 153
18 23 31 0 102 153
16 9 23 0 102 153
12 2 24 204 153 153
4 10 23 0 102 153
2 19 33 0 102 153
18 19 33 0 102 153
2 20 32 0 102 153
18 20 32 0 102 153
2 19 32 0 102 153
18 19 32 0 102 153
2 18 33 0 102 153
18 18 33 0 102 153
3 18 34 0 102 153
17 18 34 0 102 153
3 17 34 0 102 153
16 10 23 0 102 153
8 2 24 204 153 153
10 0 28 34 34 34
4 11 23 0 102 153
17 17 34 0 102 153
4 16 34 0 102 153
16 16 34 0 102 153
4 15 34 0 102 153
16 15 34 0 102 153
17 16 34 0 102 153
3 16 34 0 102 153
3 15 34 0 102 153
17 15 34 0 102 153
3 14 34 0 102 153
17 14 34 0 102 153
16 11 23 0 102 153
4 8 34 0 102 153
4 12 23 0 102 153
4 14 34 0 102 153
16 14 34 0 102 153
4 13 34 0 102 153
16 13 34 0 102 153
2 13 33 0 102 153
18 13 33 0 102 153
2 14 33 0 102 153
18 14 33 0 102 153
3 11 33 0 102 153
17 11 33 0 102 153
3 12 33 0 102 153
16 12 23 0 102 153
4 13 23 0 102 153
5 13 23 0 102 153
17 12 33 0 102 153
3 12 32 0 102 153
17 12 32 0 102 153
3 13 33 0 102 153
17 13 33 0 102 153
2 15 33 0 102 153
18 15 33 0 102 153
2 16 33 0 102 153
18 16 33 0 102 153
15 13 23 0 102 153
16 13 23 0 102 153
5 14 23 0 102 153
6 14 23 0 102 153
2 17 33 0 102 153
18 17 33 0 102 153
2 18 32 0 102 153
18 18 32 0 102 153
2 17 32 0 102 153
18 17 32 0 102 153
2 16 32 0 102 153
14 14 23 0 102 153
15 14 23 0 102 153
5 15 23 0 102 153
6 15 23 0 102 153
7 15 23 0 102 153
8 15 23 0 102 153
9 15 23 0 102 153
10 15 23 0 102 153
11 15 23 0 102 153
12 15 23 0 102 153
13 15 23 0 102 153
14 15 23 0 102 153
15 15 23 0 102 153
7 16 23 0 102 153
8 16 23 0 102 153
9 16 23 0 102 153
10 16 23 0 102 153
11 16 23 0 102 153
12 16 23 0 102 153
13 16 23 0 102 153
6 20 27 0 102 153
16 22 31 0 102 153
14 20 27 0 102 153
18 16 32 0 102 153
8 4 24 102 0 51
8 2 25 204 153 153
8 3 23 204 153 153
12 2 25 204 153 153
12 4 24 102 0 51
2 15 32 0 102 153
6 5 24 0 102 153
18 15 32 0 102 153
2 14 32 0 102 153
9 5 24 102 0 51
10 5 24 17 17 17
11 5 24 102 0 51
18 14 32 0 102 153
2 22 32 0 102 153
14 5 24 0 102 153
5 6 24 0 102 153
18 22 32 0 102 153
17 25 30 0 102 153
3 25 30 0 102 153
3 24 31 0 102 153
17 24 31 0 102 153
3 23 31 0 102 153
17 23 31 0 102 153
3 23 32 0 102 153
17 23 32 0 102 153
15 6 24 0 102 153
4 7 24 0 102 153
3 22 32 0 102 153
17 22 32 0 102 153
2 21 32 0 102 153
18 21 32 0 102 153
3 21 32 0 102 153
17 21 32 0 102 153
3 20 33 0 102 153
17 20 33 0 102 153
3 20 32 0 102 153
17 20 32 0 102 153
3 19 33 0 102 153
16 7 24 0 102 153
8 4 32 0 102 153
4 8 24 0 102 153
17 19 33 0 102 153
7 25 25 0 102 153
13 25 25 0 102 153
7 24 25 0 102 153
13 24 25 0 102 153
13 25 24 0 102 153
7 25 24 0 102 153
7 24 26 0 102 153
13 24 26 0 102 153
7 23 27 0 102 153
13 23 27 0 102 153
16 8 24 0 102 153
4 5 29 0 102 153
15 4 27 204 153 153
4 9 24 0 102 153
7 22 28 0 102 153
13 22 28 0 102 153
8 21 28 0 102 153
12 21 28 0 102 153
8 22 27 0 102 153
12 22 27 0 102 153
9 21 27 0 102 153
11 21 27 0 102 153
9 20 27 0 102 153
11 20 27 0 102 153
9 19 26 0 102 153
16 9 24 0 102 153
6 3 27 204 153 153
3 10 24 0 102 153
11 19 26 0 102 153
9 19 27 0 102 153
11 19 27 0 102 153
9 19 28 0 102 153
11 19 28 0 102 153
8 20 28 0 102 153
12 20 28 0 102 153
6 22 27 0 102 153
14 22 27 0 102 153
6 21 28 0 102 153
14 21 28 0 102 153
6 19 29 0 102 153
14 19 29 0 102 153
17 10 24 0 102 153
3 11 24 0 102 153
7 20 29 0 102 153
13 20 29 0 102 153
7 19 29 0 102 153
13 19 29 0 102 153
6 18 29 0 102 153
14 18 29 0 102 153
7 18 29 0 102 153
13 18 29 0 102 153
9 2 25 119 119 119
11 2 25 119 119 119
10 2 25 119 119 119
10 1 26 204 153 153
4 22 31 0 102 153
17 11 24 0 102 153
3 12 24 0 102 153
8 19 28 0 102 153
12 19 28 0 102 153
7 21 28 0 102 153
13 21 28 0 102 153
7 19 26 0 102 153
13 19 26 0 102 153
6 18 26 0 102 153
14 18 26 0 102 153
6 19 27 0 102 153
14 19 27 0 102 153
6 18 27 0 102 153
14 18 27 0 102 153
13 23 25 0 102 153
17 12 24 0 102 153
9 2 26 204 153 153
4 13 24 0 102 153
7 23 25 0 102 153
4 17 31 0 102 153
16 17 31 0 102 153
4 16 31 0 102 153
16 16 31 0 102 153
4 20 33 0 102 153
16 20 33 0 102 153
5 18 33 0 102 153
15 18 33 0 102 153
3 19 32 0 102 153
17 19 32 0 102 153
16 13 24 0 102 153
11 2 26 204 153 153
4 14 24 0 102 153
5 19 32 0 102 153
15 19 32 0 102 153
5 18 32 0 102 153
15 18 32 0 102 153
6 15 33 0 102 153
14 15 33 0 102 153
5 17 33 0 102 153
15 17 33 0 102 153
5 16 33 0 102 153
15 16 33 0 102 153
5 15 33 0 102 153
16 14 24 0 102 153
5 15 24 0 102 153
15 15 33 0 102 153
5 16 32 0 102 153
15 16 32 0 102 153
5 17 32 0 102 153
15 17 32 0 102 153
13 22 26 0 102 153
7 22 26 0 102 153
4 21 32 0 102 153
16 21 32 0 102 153
15 15 24 0 102 153
6 16 24 0 102 153
4 20 32 0 102 153
16 20 32 0 102 153
4 19 32 0 102 153
10 16 24 0 102 153
16 19 32 0 102 153
4 18 32 0 102 153
16 18 32 0 102 153
14 16 24 0 102 153
7 17 24 0 102 153
4 17 33 0 102 153
9 17 24 0 102 153
8 18 24 0 102 153
11 17 24 0 102 153
16 17 33 0 102 153
13 17 24 0 102 153
9 3 25 119 119 119
10 3 25 17 17 17
11 3 25 119 119 119
16 18 33 0 102 153
4 18 33 0 102 153
3 18 32 0 102 153
9 4 25 119 119 119
12 3 23 204 153 153
11 4 25 119 119 119
16 19 33 0 102 153
4 19 33 0 102 153
17 18 32 0 102 153
5 5 25 0 102 153
3 17 32 0 102 153
17 17 32 0 102 153
5 14 33 0 102 153
15 14 33 0 102 153
4 12 33 0 102 153
16 12 33 0 102 153
7 11 35 0 102 153
13 11 35 0 102 153
7 10 35 0 102 153
15 5 25 0 102 153
4 6 25 0 102 153
13 10 35 0 102 153
8 13 35 0 102 153
12 13 35 0 102 153
8 14 35 0 102 153
12 14 35 0 102 153
8 15 34 0 102 153
12 15 34 0 102 153
8 16 34 0 102 153
12 16 34 0 102 153
9 19 34 0 102 153
11 19 34 0 102 153
16 6 25 0 102 153
16 5 29 0 102 153
4 7 25 0 102 153
9 18 35 0 102 153
11 18 35 0 102 153
9 17 35 0 102 153
11 17 35 0 102 153
9 16 35 0 102 153
11 16 35 0 102 153
9 17 34 0 102 153
11 17 34 0 102 153
9 18 34 0 102 153
11 18 34 0 102 153
10 23 33 0 102 153
16 7 25 0 102 153
6 5 32 0 102 153
3 8 25 0 102 153
10 17 34 0 102 153
10 18 34 0 102 153
10 19 34 0 102 153
10 20 34 0 102 153
10 21 34 0 102 153
10 22 34 0 102 153
9 16 36 0 102 153
11 16 36 0 102 153
11 15 36 0 102 153
9 15 36 0 102 153
11 14 36 0 102 153
9 14 36 0 102 153
11 13 36 0 102 153
17 8 25 0 102 153
3 9 25 0 102 153
9 13 36 0 102 153
11 15 35 0 102 153
9 15 35 0 102 153
12 12 35 0 102 153
8 12 35 0 102 153
11 8 35 0 102 153
9 8 35 0 102 153
13 14 34 0 102 153
7 14 34 0 102 153
14 13 34 0 102 153
13 13 34 0 102 153
7 13 34 0 102 153
6 13 34 0 102 153
17 9 25 0 102 153
6 3 26 204 153 153
3 10 25 0 102 153
14 12 34 0 102 153
13 12 34 0 102 153
7 12 34 0 102 153
6 12 34 0 102 153
14 11 34 0 102 153
6 11 34 0 102 153
14 10 34 0 102 153
6 10 34 0 102 153
14 9 34 0 102 153
6 9 34 0 102 153
14 8 34 0 102 153
13 8 34 0 102 153
7 8 34 0 102 153
17 10 25 0 102 153
14 3 26 204 153 153
6 3 25 204 153 153
3 11 25 0 102 153
6 8 34 0 102 153
13 7 34 0 102 153
12 7 34 0 102 153
11 7 34 0 102 153
9 7 34 0 102 153
8 7 34 0 102 153
7 7 34 0 102 153
11 6 34 0 102 153
10 6 34 0 102 153
9 6 34 0 102 153
11 16 33 0 102 153
10 16 33 0 102 153
9 16 33 0 102 153
17 11 25 0 102 153
14 3 25 204 153 153
3 12 25 0 102 153
13 15 33 0 102 153
12 15 33 0 102 153
8 15 33 0 102 153
7 15 33 0 102 153
14 14 33 0 102 153
6 14 33 0 102 153
15 13 33 0 102 153
5 13 33 0 102 153
15 12 33 0 102 153
5 12 33 0 102 153
16 11 33 0 102 153
15 11 33 0 102 153
5 11 33 0 102 153
17 12 25 0 102 153
3 13 25 0 102 153
4 11 33 0 102 153
16 10 33 0 102 153
15 10 33 0 102 153
5 10 33 0 102 153
4 10 33 0 102 153
15 9 33 0 102 153
5 9 33 0 102 153
15 8 33 0 102 153
5 8 33 0 102 153
14 7 33 0 102 153
6 7 33 0 102 153
13 6 33 0 102 153
12 6 33 0 102 153
17 13 25 0 102 153
8 6 33 0 102 153
4 14 25 0 102 153
7 6 33 0 102 153
11 5 33 0 102 153
10 5 33 0 102 153
9 5 33 0 102 153
11 17 32 0 102 153
10 17 32 0 102 153
9 17 32 0 102 153
13 16 32 0 102 153
12 16 32 0 102 153
8 16 32 0 102 153
7 16 32 0 102 153
16 14 25 0 102 153
14 5 32 0 102 153
4 15 25 0 102 153
14 15 32 0 102 153
6 15 32 0 102 153
17 11 32 0 102 153
3 11 32 0 102 153
17 10 32 0 102 153
3 10 32 0 102 153
16 9 32 0 102 153
4 9 32 0 102 153
16 8 32 0 102 153
4 8 32 0 102 153
15 7 32 204 153 153
16 15 25 0 102 153
5 16 25 0 102 153
5 7 32 204 153 153
16 7 34 204 153 153
14 6 32 0 102 153
6 6 32 0 102 153
17 6 35 0 102 153
13 5 32 0 102 153
12 5 32 0 102 153
8 5 32 0 102 153
7 5 32 0 102 153
15 16 25 0 102 153
6 17 25 0 102 153
11 4 32 0 102 153
10 4 32 0 102 153
9 17 25 0 102 153
10 17 25 0 102 153
11 17 25 0 102 153
9 4 32 0 102 153
13 17 31 0 102 153
14 17 25 0 102 153
16 16 29 0 102 153
4 16 29 0 102 153
5 17 29 0 102 153
12 17 31 0 102 153
11 17 31 0 102 153
10 17 31 0 102 153
9 17 31 0 102 153
8 17 31 0 102 153
7 17 31 0 102 153
14 16 31 0 102 153
6 16 31 0 102 153
15 15 31 0 102 153
5 15 31 0 102 153
9 4 22 204 153 153
10 4 22 204 153 153
17 11 31 0 102 153
3 11 31 0 102 153
17 10 31 0 102 153
3 10 31 0 102 153
17 9 31 0 102 153
3 9 31 0 102 153
8 4 23 204 153 153
16 8 31 0 102 153
4 8 31 0 102 153
11 4 22 204 153 153
16 7 31 0 102 153
4 7 31 0 102 153
15 6 31 0 102 153
4 6 26 0 102 153
5 6 31 0 102 153
11 18 30 0 102 153
10 18 30 0 102 153
9 18 30 0 102 153
14 17 30 0 102 153
13 17 30 0 102 153
12 17 30 0 102 153
8 17 30 0 102 153
7 17 30 0 102 153
6 17 30 0 102 153
15 16 30 0 102 153
16 6 26 0 102 153
15 4 26 204 153 153
4 7 26 0 102 153
5 16 30 0 102 153
16 15 30 0 102 153
4 15 30 0 102 153
10 3 23 238 238 238
5 5 31 0 102 153
12 2 26 204 153 153
17 11 30 0 102 153
3 11 30 0 102 153
8 2 26 204 153 153
17 10 30 0 102 153
3 10 30 0 102 153
16 7 26 0 102 153
5 4 27 204 153 153
3 8 26 0 102 153
17 9 30 0 102 153
3 9 30 0 102 153
17 8 30 0 102 153
3 8 30 0 102 153
7 4 23 204 153 153
16 7 30 0 102 153
4 7 30 0 102 153
12 4 23 204 153 153
16 6 30 0 102 153
4 6 30 0 102 153
15 5 30 0 102 153
5 5 30 0 102 153
14 4 30 238 238 238
17 8 26 0 102 153
10 3 31 0 102 153
3 9 26 0 102 153
13 4 30 0 102 51
7 4 30 0 102 51
6 4 30 238 238 238
11 3 30 0 102 153
10 3 30 0 102 153
9 3 30 0 102 153
12 18 29 0 102 153
11 18 29 0 102 153
10 18 29 0 102 153
9 18 29 0 102 153
8 18 29 0 102 153
16 15 29 0 102 153
4 15 29 0 102 153
17 9 26 0 102 153
13 3 31 0 102 153
7 3 31 0 102 153
3 10 26 0 102 153
9 2 27 204 153 153
12 2 27 204 153 153
17 13 29 0 102 153
3 13 29 0 102 153
17 12 29 0 102 153
3 12 29 0 102 153
17 11 29 0 102 153
3 11 29 0 102 153
13 3 24 204 153 153
17 10 29 0 102 153
3 10 29 0 102 153
7 3 24 204 153 153
12 3 24 204 153 153
17 10 26 0 102 153
8 3 30 0 102 153
12 3 30 0 102 153
3 11 26 0 102 153
17 9 29 0 102 153
3 9 29 0 102 153
8 3 24 204 153 153
17 8 29 0 102 153
3 8 29 0 102 153
5 4 26 204 153 153
16 7 29 0 102 153
4 7 29 0 102 153
15 4 25 204 153 153
16 6 29 0 102 153
4 6 29 0 102 153
15 5 29 238 238 238
5 5 29 238 238 238
17 11 26 0 102 153
13 3 29 34 34 34
7 3 29 34 34 34
3 12 26 0 102 153
14 4 29 238 238 238
6 4 29 238 238 238
12 3 29 238 238 238
11 3 29 0 102 153
10 3 29 0 102 153
9 3 29 0 102 153
8 3 29 238 238 238
10 18 28 0 102 153
16 16 28 0 102 153
4 16 28 0 102 153
8 2 27 204 153 153
16 15 28 0 102 153
4 15 28 0 102 153
17 12 26 0 102 153
13 3 28 0 102 51
3 13 26 0 102 153
13 3 27 204 153 153
17 14 28 0 102 153
3 14 28 0 102 153
11 3 23 238 238 238
17 13 28 0 102 153
3 13 28 0 102 153
9 3 23 238 238 238
14 3 28 204 153 153
17 12 28 0 102 153
3 12 28 0 102 153
6 3 28 204 153 153
15 4 28 204 153 153
17 11 28 0 102 153
17 13 26 0 102 153
11 2 27 204 153 153
4 14 26 0 102 153
3 11 28 0 102 153
5 4 28 204 153 153
16 4 27 204 153 153
17 10 28 0 102 153
3 10 28 0 102 153
4 4 27 204 153 153
16 5 26 204 153 153
17 9 28 0 102 153
3 9 28 0 102 153
4 5 26 204 153 153
10 1 27 204 153 153
16 14 26 0 102 153
10 2 27 204 153 153
4 15 26 0 102 153
17 8 28 0 102 153
3 8 28 0 102 153
7 3 28 0 102 51
17 7 28 0 102 153
3 7 28 0 102 153
6 4 24 204 153 153
16 6 28 0 102 153
4 6 28 0 102 153
13 4 23 204 153 153
16 5 28 0 102 153
4 5 28 0 102 153
16 15 26 0 102 153
5 16 26 0 102 153
12 3 28 238 238 238
11 3 28 0 102 153
10 3 28 0 102 153
9 3 28 0 102 153
8 3 28 238 238 238
10 18 27 0 102 153
16 16 27 0 102 153
4 16 27 0 102 153
7 3 27 204 153 153
15 16 26 0 102 153
6 17 26 0 102 153
16 15 27 0 102 153
4 15 27 0 102 153
14 3 27 204 153 153
10 17 26 0 102 153
17 14 27 0 102 153
3 14 27 0 102 153
9 3 31 0 102 153
14 17 26 0 102 153
17 13 27 0 102 153
9 18 26 0 102 153
15 17 29 0 102 153
11 18 26 0 102 153
3 13 27 0 102 153
11 3 31 0 102 153
8 3 31 0 102 153
17 12 27 0 102 153
3 12 27 0 102 153
12 3 31 0 102 153
6 4 31 0 102 153
17 11 27 0 102 153
3 11 27 0 102 153
14 4 31 0 102 153
15 5 31 0 102 153
17 10 27 0 102 153
3 10 27 0 102 153
9 3 22 204 153 153
10 3 22 204 153 153
4 5 27 0 102 153
17 9 27 0 102 153
3 9 27 0 102 153
11 3 22 204 153 153
10 4 25 17 17 17
17 8 27 0 102 153
3 8 27 0 102 153
13 4 32 0 102 153
17 7 27 0 102 153
3 7 27 0 102 153
5 4 25 204 153 153
16 6 27 0 102 153
16 5 27 0 102 153
14 4 24 204 153 153
4 6 27 0 102 153
